Workbook

Sheet Read me
A1: Goods and Services Tax - GSTR-2B
A4: Financial Year | C4: 2025-26
A5: Tax Period | C5: September
A6: GSTIN | C6: 33AAWFM5806A1ZD
A7: Legal Name | C7: MAHAALAXMI CERAMICS
A8: Trade Name (if any) | C8: MAHAALAXMI CERAMICS
A9: Date of generation | C9: 14/10/2025
A11: GSTR-2B Data Entry Instructions
A12: Worksheet Name | B12: GSTR-2B Table Reference | C12: Field Name | D12: Instructions
A13: B2B | B13: Taxable inward supplies received from registered person | C13: GSTIN of Supplier | D13: GSTIN of supplier
C14: Trade/Legal name | D14: Trade name of the supplier will be displayed. If trade name is not available, then legal name of the supplier
C15: Invoice number | D15: Invoice number
C16: Invoice type | D16: Invoice type can be derived based on the following types R- Regular (Other than SEZ supplies and Deemed exports) SEZWP- SEZ supplies with payment of tax SEZWOP- SEZ supplies with out payment of tax DE- Deemed exports CBW - Intra-State Supplies attracting IGST
C17: Invoice date | D17: Invoice date format shall be DD-MM-YYYY
C18: Invoice value | D18: Invoice value (in rupees)
C19: Place of supply | D19: Place of supply shall be the place where goods are supplied or services are provided (As declared by the supplier)
C20: Supply attract Reverse charge | D20: Supply attract reverse charge divided into two types: Y- Purchases attract reverse charge N- Purchases don’t attract reverse charge
C21: Taxable value | D21: Taxable value
C22: Integrated Tax | D22: Integrated Tax amount (In rupees)
C23: Central Tax | D23: Central Tax amount (In rupees)
C24: State/UT tax | D24: State/UT tax amount (In rupees)
C25: Cess | D25: Cess amount (In rupees)
... C33: IRN date | D33: This is the date of invoice reference number, auto-populated from e-invoice. For the documents uploaded by the supplier, this shall be blank.
A34: B2BA | B34: Amendments to previously uploaded invoices by supplier | C34: Invoice number (Original details) | D34: Original invoice number
C35: Invoice date (Original details) | D35: Original invoice date (Date format shall be DD-MM-YYYY)
C36: GSTIN of Supplier | D36: GSTIN of supplier
C37: Trade/Legal name | D37: Trade name of the supplier will be displayed. If trade name is not available then legal name of the supplier.
C38: Invoice number | D38: Revised Invoice number
C39: Invoice type | D39: Invoice type can be derived based on the following types R- Regular (Other than SEZ supplies and Deemed exports) SEZWP- SEZ supplies with payment of tax SEZWOP- SEZ supplies with out payment of tax DE- Deemed exports CBW - Intra-State Supplies attracting IGST
C40: Invoice date | D40: Invoice date format shall be DD-MM-YYYY
C41: Invoice value | D41: Invoice value (in rupees)
C42: Place of supply | D42: Place of supply shall be the place where goods supplied or services provided (As declared by the supplier)
C43: Supply attract Reverse charge | D43: Supply attract reverse charge divided in to two types Y- Purchases attract reverse charge N- Purchases don’t attract reverse charge
C44: Taxable value | D44: Taxable value (In rupees)
C45: Integrated Tax | D45: Integrated Tax amount (In rupees)
C46: Central Tax | D46: Central Tax amount (In rupees)
... C58: Applicable % of Tax Rate | D58: If the supply is eligible to be taxed at 65% of the existing rate of tax, it shall be 65%, else blank
A59: B2B-CDNR | B59: Debit/Credit notes(Original) | C59: GSTIN of Supplier | D59: GSTIN of supplier
C60: Trade/Legal name | D60: Trade name of the supplier will be displayed. If trade name is not available then legal name of the supplier
C61: Note number | D61: Debit/Credit note number
...

Sheet ITC Available
A1: FORM GSTR-2B
A2: FORM GSTR-2B has been generated on the basis of the information furnished by your suppliers in their respective FORMS GSTR-1/IFF, 5 and 6. It also contains information on imports of goods from the ICEGATE system. This information is for guidance purposes only.
A5: FORM SUMMARY - ITC Available
A6: S.no. | B6: Heading | C6: GSTR-3B table | D6: Integrated Tax (₹) | E6: Central Tax (₹) | F6: State/UT Tax (₹) | G6: Cess (₹) | H6: Advisory
A7: Credit which may be availed under FORM GSTR-3B
A8: Part A | B8: ITC Available - Credit may be claimed in relevant headings in GSTR-3B
A9: I | B9: All other ITC - Supplies from registered persons other than reverse charge (IMS) | C9: 4(A)(5) | D9: 2493968.2 | E9: 495516.31 | F9: 495516.31 | G9: 0 | H9: Net input tax credit may be availed under Table 4(A)(5) of FORM GSTR-3B.
A10: Details | B10: B2B - Invoices (IMS) | D10: 2493226.1 | E10: 495516.31 | F10: 495516.31 | G10: 0
B11: B2B - Debit notes (IMS) | D11: 742.12 | E11: 0 | F11: 0 | G11: 0
B12: ECO - Documents (IMS) | D12: 0 | E12: 0 | F12: 0 | G12: 0
B13: B2B - Invoices (Amendment) (IMS) | D13: 0 | E13: 0 | F13: 0 | G13: 0
B14: B2B - Debit notes (Amendment) (IMS) | D14: 0 | E14: 0 | F14: 0 | G14: 0
B15: ECO - Documents (Amendment) (IMS) | D15: 0 | E15: 0 | F15: 0 | G15: 0
A16: II | B16: Inward Supplies from ISD | C16: 4(A)(4) | D16: 0 | E16: 0 | F16: 0 | G16: 0 | H16: Net input tax credit may be availed under Table 4(A)(4) of FORM GSTR-3B.
A17: Details | B17: ISD - Invoices | D17: 0 | E17: 0 | F17: 0 | G17: 0
B18: ISD - Invoices (Amendment) | D18: 0 | E18: 0 | F18: 0 | G18: 0
A19: III | B19: Inward Supplies liable for reverse charge | C19: 3.1(d) 4(A)(3) | D19: 30254.85 | E19: 82.5 | F19: 82.5 | G19: 0 | H19: These supplies shall be declared in Table 3.1(d) of FORM GSTR-3B for payment of tax. Net input tax credit may be availed under Table 4(A)(3) of FORM GSTR-3B on payment of tax.
A20: Details | B20: B2B - Invoices | D20: 30254.85 | E20: 82.5 | F20: 82.5 | G20: 0
B21: B2B - Debit notes | D21: 0 | E21: 0 | F21: 0 | G21: 0
B22: B2B - Invoices (Amendment) | D22: 0 | E22: 0 | F22: 0 | G22: 0
B23: B2B - Debit notes (Amendment) | D23: 0 | E23: 0 | F23: 0 | G23: 0
A24: IV | B24: Import of Goods | C24: 4(A)(1) | D24: 0 | E24: 0 | F24: 0 | G24: 0 | H24: Net input tax credit may be availed under Table 4(A)(1) of FORM GSTR-3B.
A25: Details | B25: IMPG - Import of goods from overseas | D25: 0 | E25: 0 | F25: 0 | G25: 0
B26: IMPG (Amendment) | D26: 0 | E26: 0 | F26: 0 | G26: 0
B27: IMPGSEZ - Import of goods from SEZ | D27: 0 | E27: 0 | F27: 0 | G27: 0
B28: IMPGSEZ (Amendment) | D28: 0 | E28: 0 | F28: 0 | G28: 0
A29: Part B | B29: ITC Available - Credit notes should be net off against relevant ITC available headings in GSTR-3B
A30: I | B30: Others | C30: 4(A) | D30: 15562.33 | E30: 1657.44 | F30: 1657.44 | G30: 0 | H30: Credit Notes shall be net-off against relevant ITC available tables [Table 4A(3,4,5)]. Liability against Credit Notes (Reverse Charge) shall be net-off in Table 3.1(d).
A31: Details | B31: B2B - Credit notes (IMS) | C31: 4(A)(5) | D31: 15562.33 | E31: 1657.44 | F31: 1657.44 | G31: 0
B32: B2B - Credit notes (Amendment) (IMS) | C32: 4(A)(5) | D32: 0 | E32: 0 | F32: 0 | G32: 0
B33: B2B - Credit notes (Reverse charge) | C33: 3.1(d) 4(A)(3) | D33: 0 | E33: 0 | F33: 0 | G33: 0
B34: B2B - Credit notes (Reverse charge)(Amendment) | C34: 3.1(d) 4(A)(3) | D34: 0 | E34: 0 | F34: 0 | G34: 0
B35: ISD - Credit notes | C35: 4(A)(4) | D35: 0 | E35: 0 | F35: 0 | G35: 0
B36: ISD - Credit notes (Amendment) | C36: 4(A)(4) | D36: 0 | E36: 0 | F36: 0 | G36: 0

Sheet ITC not available
A1: FORM GSTR-2B
A2: FORM GSTR-2B has been generated on the basis of the information furnished by your suppliers in their respective FORMS GSTR-1/IFF, 5 and 6. It also contains information on imports of goods from the ICEGATE system. This information is for guidance purposes only.
A5: FORM SUMMARY - ITC Not Available
A6: S.no. | B6: Heading | C6: GSTR-3B table | D6: Integrated Tax (₹) | E6: Central Tax (₹) | F6: State/UT Tax (₹) | G6: Cess (₹) | H6: Advisory
A7: Credit which may not be availed under FORM GSTR-3B
A8: Part A | B8: ITC Not Available
A9: I | B9: All other ITC - Supplies from registered persons other than reverse charge | C9: 4(D)(2) | D9: 0 | E9: 0 | F9: 0 | G9: 0 | H9: Such credit shall not be taken and has to be reported in table 4(D)(2) of FORM GSTR-3B.
A10: Details | B10: B2B - Invoices | D10: 0 | E10: 0 | F10: 0 | G10: 0
B11: B2B - Debit notes | D11: 0 | E11: 0 | F11: 0 | G11: 0
B12: ECO - Documents | D12: 0 | E12: 0 | F12: 0 | G12: 0
B13: B2B - Invoices (Amendment) | D13: 0 | E13: 0 | F13: 0 | G13: 0
B14: B2B - Debit notes (Amendment) | D14: 0 | E14: 0 | F14: 0 | G14: 0
B15: ECO - Documents (Amendment) | D15: 0 | E15: 0 | F15: 0 | G15: 0
A16: II | B16: Inward Supplies from ISD | C16: 4(D)(2) | D16: 0 | E16: 0 | F16: 0 | G16: 0 | H16: Such credit shall not be taken and has to be reported in table 4(D)(2) of FORM GSTR-3B.
A17: Details | B17: ISD - Invoices | D17: 0 | E17: 0 | F17: 0 | G17: 0
B18: ISD - Invoices (Amendment) | D18: 0 | E18: 0 | F18: 0 | G18: 0
A19: III | B19: Inward Supplies liable for reverse charge | C19: 3.1(d) 4(D)(2) | D19: 0 | E19: 0 | F19: 0 | G19: 0 | H19: These supplies shall be declared in Table 3.1(d) of FORM GSTR-3B for payment of tax. However, credit will not be available on the same and has to be reported in table 4(D)(2) of FORM GSTR-3B.
A20: Details | B20: B2B - Invoices | D20: 0 | E20: 0 | F20: 0 | G20: 0
B21: B2B - Debit notes | D21: 0 | E21: 0 | F21: 0 | G21: 0
B22: B2B - Invoices (Amendment) | D22: 0 | E22: 0 | F22: 0 | G22: 0
B23: B2B - Debit notes (Amendment) | D23: 0 | E23: 0 | F23: 0 | G23: 0
A24: Part B | B24: ITC Not Available - Credit notes should be net off against relevant ITC available headings in GSTR-3B
A25: I | B25: Others | C25: 4(A) | D25: 0 | E25: 0 | F25: 0 | G25: 0 | H25: Credit Notes should be net-off against relevant ITC available tables [Table 4A(3,4,5)].
A26: Details | B26: B2B - Credit notes | C26: 4(A)(5) | D26: 0 | E26: 0 | F26: 0 | G26: 0
B27: B2B - Credit notes (Amendment) | C27: 4(A)(5) | D27: 0 | E27: 0 | F27: 0 | G27: 0
B28: B2B - Credit notes (Reverse charge) | C28: 4(A)(3) | D28: 0 | E28: 0 | F28: 0 | G28: 0
B29: B2B - Credit notes (Reverse charge)(Amendment) | C29: 4(A)(3) | D29: 0 | E29: 0 | F29: 0 | G29: 0
B30: ISD - Credit notes | C30: 4(A)(4) | D30: 0 | E30: 0 | F30: 0 | G30: 0
B31: ISD - Credit notes (Amendment) | C31: 4(A)(4) | D31: 0 | E31: 0 | F31: 0 | G31: 0

Sheet ITC Reversal
A1: FORM GSTR-2B
A2: FORM GSTR-2B has been generated on the basis of the information furnished by your suppliers in their respective FORMS GSTR-1/IFF, 5 and 6. It also contains information on imports of goods from the ICEGATE system. This information is for guidance purposes only.
A5: FORM SUMMARY - ITC Reversal
A6: S.no. | B6: Heading | C6: GSTR-3B table | D6: Integrated Tax (₹) | E6: Central Tax (₹) | F6: State/UT Tax (₹) | G6: Cess (₹) | H6: Advisory
A7: Credit which may not be availed under FORM GSTR-3B
A8: Part A | B8: ITC Reversed - Others
A9: I | B9: ITC Reversal on account of Rule 37A | C9: 4(B)(2) | D9: 0 | E9: 0 | F9: 0 | G9: 0 | H9: Such credit shall be reversed and has to be reported in table 4(B)(2) of FORM GSTR-3B
A10: Details | B10: B2B - Invoices | D10: 0 | E10: 0 | F10: 0 | G10: 0
B11: B2B - Debit notes | D11: 0 | E11: 0 | F11: 0 | G11: 0
B12: B2B - Invoices (Amendment) | D12: 0 | E12: 0 | F12: 0 | G12: 0
B13: B2B - Debit notes (Amendment) | D13: 0 | E13: 0 | F13: 0 | G13: 0

Sheet ITC Rejected
A1: FORM GSTR-2B
A2: FORM GSTR-2B has been generated on the basis of the information furnished by your suppliers in their respective FORMS GSTR-1/IFF including E-Commerce supplies, 5 and 6. It also contains information on imports of goods from the ICEGATE system. This information is for guidance purposes only.
A5: FORM SUMMARY - ITC Rejected
A6: S.no. | B6: Heading | C6: GSTR-3B table | D6: Integrated Tax (₹) | E6: Central Tax (₹) | F6: State/UT Tax (₹) | G6: Cess (₹) | H6: Advisory
A7: Credit which is rejected on IMS Dashboard
A8: Part A | B8: ITC Rejected - Others
A9: I | B9: All other ITC - Supplies from registered persons other than reverse charge (IMS) | C9: NA | D9: 0 | E9: 0 | F9: 0 | G9: 0 | H9: Input tax credit cannot be availed in FORM GSTR-3B.
A10: Details | B10: B2B - Invoices (IMS) | D10: 0 | E10: 0 | F10: 0 | G10: 0
B11: B2B - Debit notes (IMS) | D11: 0 | E11: 0 | F11: 0 | G11: 0
B12: ECO - Documents (IMS) | D12: 0 | E12: 0 | F12: 0 | G12: 0
B13: B2B - Invoices (Amendment) (IMS) | D13: 0 | E13: 0 | F13: 0 | G13: 0
B14: B2B - Debit notes (Amendment) (IMS) | D14: 0 | E14: 0 | F14: 0 | G14: 0
B15: ECO - Documents (Amendment) (IMS) | D15: 0 | E15: 0 | F15: 0 | G15: 0
A16: II | B16: Inward Supplies from ISD | C16: NA | D16: 0 | E16: 0 | F16: 0 | G16: 0 | H16: Input tax credit cannot be availed in FORM GSTR-3B.
A17: Details | B17: ISD - Invoices | D17: 0 | E17: 0 | F17: 0 | G17: 0
B18: ISD - Invoices (Amendment) | D18: 0 | E18: 0 | F18: 0 | G18: 0
A19: Part B | B19: Rejected Records - Credit notes rejected on IMS Dashboard
A20: I | B20: Others | C20: NA | D20: 0 | E20: 0 | F20: 0 | G20: 0 | H20: These Credit Notes are not eligible to net-off against relevant ITC available tables [Table 4A(4,5)].
A21: Details | B21: B2B - Credit notes (IMS) | C21: NA | D21: 0 | E21: 0 | F21: 0 | G21: 0
B22: B2B - Credit notes (Amendment) (IMS) | C22: NA | D22: 0 | E22: 0 | F22: 0 | G22: 0
B23: ISD - Credit notes | C23: NA | D23: 0 | E23: 0 | F23: 0 | G23: 0
B24: ISD - Credit notes (Amendment) | C24: NA | D24: 0 | E24: 0 | F24: 0 | G24: 0

Sheet B2B
A1: Goods and Services Tax - GSTR-2B
A2: Taxable inward supplies received from registered persons
A3: GSTIN of supplier | B3: Trade/Legal name | C3: Invoice number | D3: Invoice type | E3: Invoice Date | F3: Invoice Value(₹) | G3: Place of supply | H3: Supply Attract Reverse Charge | I3: Taxable Value (₹) | J3: Integrated Tax(₹) | K3: Central Tax(₹) | L3: State/UT Tax(₹) | M3: Cess(₹) | N3: GSTR-1/IFF/GSTR-5 Period | O3: GSTR-1/IFF/GSTR-5 Filing Date | P3: ITC Availability | Q3: Reason | R3: Applicable % of Tax Rate | S3: Source | T3: IRN | U3: IRN Date
A4: 33AABCV3125B1Z1 | B4: VALLI STEEL INDUSTRIES PVT. LTD. | C4: 112600 | D4: Regular | E4: 45909 | F4: 5452 | G4: Tamil Nadu | H4: No | I4: 4620 | J4: 0 | K4: 415.8 | L4: 415.8 | M4: 0 | N4: Sep'25 | O4: 10/10/2025 | P4: Yes | R4: 100% | S4: E-Invoice | T4: 09f5afdb8dbb2e88ffbf7bbda6e2142db500c747d2c7bbe059f832ac0fe43f4b | U4: 09/09/2025
A5: 24AACCL6726H1ZK | B5: LASA CERA PRIVATE LIMITED | C5: GSTT/962 | D5: Regular | E5: 45926 | F5: 28405 | G5: Tamil Nadu | H5: No | I5: 24072 | J5: 4332.96 | K5: 0 | L5: 0 | M5: 0 | N5: Sep'25 | O5: 08/10/2025 | P5: Yes | R5: 100%
A6: 33AAAFE9603R1Z5 | B6: EASTERN CORPORATION | C6: FA3056 | D6: Regular | E6: 45915 | F6: 36029 | G6: Tamil Nadu | H6: No | I6: 30533.04 | J6: 0 | K6: 2747.97 | L6: 2747.97 | M6: 0 | N6: Sep'25 | O6: 10/10/2025 | P6: Yes | R6: 100% | S6: E-Invoice | T6: d3781eb7f0d8f711714f2538818c1f672ba1a866b28134c29626b51f054be5e5 | U6: 15/09/2025
A7: 33AAAFE9603R1Z5 | B7: EASTERN CORPORATION | C7: FA3097 | D7: Regular | E7: 45918 | F7: 39883 | G7: Tamil Nadu | H7: No | I7: 33799.13 | J7: 0 | K7: 3041.91 | L7: 3041.91 | M7: 0 | N7: Sep'25 | O7: 10/10/2025 | P7: Yes | R7: 100% | S7: E-Invoice | T7: ec4f4bfc9166f2947d2207f2eb0e773c20d92a27fa22e09f5f397ac734f64761 | U7: 18/09/2025
A8: 33AAAFE9603R1Z5 | B8: EASTERN CORPORATION | C8: FA3233 | D8: Regular | E8: 45925 | F8: 36410 | G8: Tamil Nadu | H8: No | I8: 30855.9 | J8: 0 | K8: 2777.03 | L8: 2777.03 | M8: 0 | N8: Sep'25 | O8: 10/10/2025 | P8: Yes | R8: 100% | S8: E-Invoice | T8: ce637b2893cdb261e72cea8069fe54989d481379708bb7d7ba01ded8817bd80c | U8: 25/09/2025
A9: 33AAAFE9603R1Z5 | B9: EASTERN CORPORATION | C9: Nex1006 | D9: Regular | E9: 45925 | F9: 12250 | G9: Tamil Nadu | H9: No | I9: 10381.3 | J9: 0 | K9: 934.32 | L9: 934.32 | M9: 0 | N9: Sep'25 | O9: 10/10/2025 | P9: Yes | R9: 100% | S9: E-Invoice | T9: c45aa93be385e140132466fff8f553b51819407cedf12e79f73c50840510e150 | U9: 25/09/2025
A10: 33AAAFE9603R1Z5 | B10: EASTERN CORPORATION | C10: Nex1007 | D10: Regular | E10: 45925 | F10: 1654 | G10: Tamil Nadu | H10: No | I10: 1401.64 | J10: 0 | K10: 126.15 | L10: 126.15 | M10: 0 | N10: Sep'25 | O10: 10/10/2025 | P10: Yes | R10: 100% | S10: E-Invoice | T10: cab2f03a379c264a6846da831b4f442a0a6e6f65d26f6ed1123edc1e9f5afff9 | U10: 25/09/2025
A11: 33AAAFE9603R1Z5 | B11: EASTERN CORPORATION | C11: Nex838 | D11: Regular | E11: 45902 | F11: 3795 | G11: Tamil Nadu | H11: No | I11: 3216.1 | J11: 0 | K11: 289.45 | L11: 289.45 | M11: 0 | N11: Sep'25 | O11: 10/10/2025 | P11: Yes | R11: 100% | S11: E-Invoice | T11: bfa4263c3e57aacb236728c8472c37403e81b3047c25d79337c6101ace328bac | U11: 02/09/2025
A12: 33AAAFE9603R1Z5 | B12: EASTERN CORPORATION | C12: Nex955 | D12: Regular | E12: 45918 | F12: 5770 | G12: Tamil Nadu | H12: No | I12: 4889.8 | J12: 0 | K12: 440.08 | L12: 440.08 | M12: 0 | N12: Sep'25 | O12: 10/10/2025 | P12: Yes | R12: 100% | S12: E-Invoice | T12: d4998913c2df0e2c5f588ab730692c678fb95a54fd32e2fd318890031fef8d29 | U12: 18/09/2025
A13: 33AAAFE9603R1Z5 | B13: EASTERN CORPORATION | C13: RA25 | D13: Regular | E13: 45925 | F13: 132000 | G13: Tamil Nadu | H13: No | I13: 111864.4 | J13: 0 | K13: 10067.8 | L13: 10067.8 | M13: 0 | N13: Sep'25 | O13: 10/10/2025 | P13: Yes | R13: 100% | S13: E-Invoice | T13: 7ec8233ac767fb04507a74ec2579df53a93fe2ac9f15601747955209796052b2 | U13: 25/09/2025
A14: 33AAACH2702H1Z7 | B14: HDFC BANK LIMITED | C14: LMS2625362605149 | D14: Regular | E14: 45910 | F14: 708 | G14: Tamil Nadu | H14: No | I14: 600 | J14: 0 | K14: 54 | L14: 54 | M14: 0 | N14: Sep'25 | O14: 10/10/2025 | P14: Yes | R14: 100%
A15: 33AAACH2702H1Z7 | B15: HDFC BANK LIMITED | C15: LMS2625362605510 | D15: Regular | E15: 45910 | F15: 59000 | G15: Tamil Nadu | H15: No | I15: 50000 | J15: 0 | K15: 4500 | L15: 4500 | M15: 0 | N15: Sep'25 | O15: 10/10/2025 | P15: Yes | R15: 100%
A16: 33AAACH2702H1Z7 | B16: HDFC BANK LIMITED | C16: LMS2625362606007 | D16: Regular | E16: 45910 | F16: 109971 | G16: Tamil Nadu | H16: No | I16: 93195.76 | J16: 0 | K16: 8387.62 | L16: 8387.62 | M16: 0 | N16: Sep'25 | O16: 10/10/2025 | P16: Yes | R16: 100%
A17: 33AAACH2702H1Z7 | B17: HDFC BANK LIMITED | C17: NCB2625361429730 | D17: Regular | E17: 45909 | F17: 73750 | G17: Tamil Nadu | H17: No | I17: 62500 | J17: 0 | K17: 5625 | L17: 5625 | M17: 0 | N17: Sep'25 | O17: 10/10/2025 | P17: Yes | R17: 100%
A18: 24AARFC2763R1ZQ | B18: CLAYROCK GRANITO LLP | C18: CLR/2526-4850 | D18: Regular | E18: 45916 | F18: 109757 | G18: Tamil Nadu | H18: No | I18: 93014 | J18: 16743 | K18: 0 | L18: 0 | M18: 0 | N18: Sep'25 | O18: 07/10/2025 | P18: Yes | R18: 100% | S18: E-Invoice | T18: 68c570b3e06ab081448b380147664752d1637bf2724be3eb976d2d0272fb4979 | U18: 16/09/2025
A19: 24AARFC2763R1ZQ | B19: CLAYROCK GRANITO LLP | C19: CLR/2526-5039 | D19: Regular | E19: 45921 | F19: 432748 | G19: Tamil Nadu | H19: No | I19: 366736 | J19: 66012 | K19: 0 | L19: 0 | M19: 0 | N19: Sep'25 | O19: 07/10/2025 | P19: Yes | R19: 100% | S19: E-Invoice | T19: 39571673be273058197d02eac37da898badae303fdf41a46cd185b31a8c394d3 | U19: 21/09/2025
A20: 33ADNFS8461M1ZC | B20: STAR MARKETING | C20: 2977 | D20: Regular | E20: 45903 | F20: 2750 | G20: Tamil Nadu | H20: No | I20: 2330.5 | J20: 0 | K20: 209.75 | L20: 209.75 | M20: 0 | N20: Sep'25 | O20: 10/10/2025 | P20: Yes | R20: 100% | S20: E-Invoice | T20: 8797cd5647a19310bcafac834609976c6692890515f787de1fb901b99ea165e8 | U20: 03/09/2025
A21: 33ADNFS8461M1ZC | B21: STAR MARKETING | C21: 3233 | D21: Regular | E21: 45916 | F21: 7875 | G21: Tamil Nadu | H21: No | I21: 6673.73 | J21: 0 | K21: 600.64 | L21: 600.64 | M21: 0 | N21: Sep'25 | O21: 10/10/2025 | P21: Yes | R21: 100% | S21: E-Invoice | T21: ea604169aff79c592fbdedf6fc65730030da974b3c15d1f1724a6c133a5b833f | U21: 16/09/2025
A22: 33ADNFS8461M1ZC | B22: STAR MARKETING | C22: 3353 | D22: Regular | E22: 45924 | F22: 4950 | G22: Tamil Nadu | H22: No | I22: 4194.9 | J22: 0 | K22: 377.54 | L22: 377.54 | M22: 0 | N22: Sep'25 | O22: 10/10/2025 | P22: Yes | R22: 100% | S22: E-Invoice | T22: 8e0a5c32c714556eb9759cbef23f9d0e57176606dd561fc9631cbd7f3752582a | U22: 24/09/2025
A23: 24AANCS6859B1Z4 | B23: SEGAL CERAMIC PRIVATE LIMITED | C23: 2526/1775 | D23: Regular | E23: 45919 | F23: 274576 | G23: Tamil Nadu | H23: No | I23: 232691.71 | J23: 41884.51 | K23: 0 | L23: 0 | M23: 0 | N23: Sep'25 | O23: 08/10/2025 | P23: Yes | R23: 100%
A24: 37AAECS0763K1Z4 | B24: SOMANY CERAMICS LIMITED | C24: 3525206222 | D24: Regular | E24: 45908 | F24: 285100.02 | G24: Tamil Nadu | H24: No | I24: 241610.18 | J24: 43489.84 | K24: 0 | L24: 0 | M24: 0 | N24: Sep'25 | O24: 11/10/2025 | P24: Yes | R24: 100%
A25: 37AAECS0763K1Z4 | B25: SOMANY CERAMICS LIMITED | C25: 3525206223 | D25: Regular | E25: 45908 | F25: 52226.49 | G25: Tamil Nadu | H25: No | I25: 44259.73 | J25: 7966.76 | K25: 0 | L25: 0 | M25: 0 | N25: Sep'25 | O25: 11/10/2025 | P25: Yes | R25: 100%
A26: 37AAECS0763K1Z4 | B26: SOMANY CERAMICS LIMITED | C26: 3525206704 | D26: Regular | E26: 45919 | F26: 515180.74 | G26: Tamil Nadu | H26: No | I26: 436593.85 | J26: 78586.89 | K26: 0 | L26: 0 | M26: 0 | N26: Sep'25 | O26: 11/10/2025 | P26: Yes | R26: 100%
A27: 37AAECS0763K1Z4 | B27: SOMANY CERAMICS LIMITED | C27: 3525206705 | D27: Regular | E27: 45919 | F27: 4839.56 | G27: Tamil Nadu | H27: No | I27: 4101.33 | J27: 738.23 | K27: 0 | L27: 0 | M27: 0 | N27: Sep'25 | O27: 11/10/2025 | P27: Yes | R27: 100%
A28: 37AAECS0763K1Z4 | B28: SOMANY CERAMICS LIMITED | C28: 3525207281 | D28: Regular | E28: 45929 | F28: 50909.63 | G28: Tamil Nadu | H28: No | I28: 43143.73 | J28: 7765.9 | K28: 0 | L28: 0 | M28: 0 | N28: Sep'25 | O28: 11/10/2025 | P28: Yes | R28: 100%
A29: 37AAECS0763K1Z4 | B29: SOMANY CERAMICS LIMITED | C29: 3525207282 | D29: Regular | E29: 45929 | F29: 45432.05 | G29: Tamil Nadu | H29: No | I29: 38501.73 | J29: 6930.32 | K29: 0 | L29: 0 | M29: 0 | N29: Sep'25 | O29: 11/10/2025 | P29: Yes | R29: 100%
A30: 37AAECS0763K1Z4 | B30: SOMANY CERAMICS LIMITED | C30: 3525207283 | D30: Regular | E30: 45929 | F30: 394981.02 | G30: Tamil Nadu | H30: No | I30: 334729.68 | J30: 60251.34 | K30: 0 | L30: 0 | M30: 0 | N30: Sep'25 | O30: 11/10/2025 | P30: Yes | R30: 100%
A31: 33CHIPS6786C2ZY | B31: SRI PALANIANDAVAR TRADERS | C31: SIT-334 | D31: Regular | E31: 45909 | F31: 13325 | G31: Tamil Nadu | H31: No | I31: 11292.54 | J31: 0 | K31: 1016.33 | L31: 1016.33 | M31: 0 | N31: Sep'25 | O31: 09/10/2025 | P31: Yes | R31: 100%
A32: 33CHIPS6786C2ZY | B32: SRI PALANIANDAVAR TRADERS | C32: SIT-339 | D32: Regular | E32: 45910 | F32: 2701 | G32: Tamil Nadu | H32: No | I32: 2288.99 | J32: 0 | K32: 206.01 | L32: 206.01 | M32: 0 | N32: Sep'25 | O32: 09/10/2025 | P32: Yes | R32: 100%
A33: 33CHIPS6786C2ZY | B33: SRI PALANIANDAVAR TRADERS | C33: SIT-342 | D33: Regular | E33: 45911 | F33: 5370 | G33: Tamil Nadu | H33: No | I33: 4550.85 | J33: 0 | K33: 409.57 | L33: 409.57 | M33: 0 | N33: Sep'25 | O33: 09/10/2025 | P33: Yes | R33: 100%
A34: 33ALAPJ2732M1ZA | B34: PHOENIX BATH INDIA | C34: 250 | D34: Regular | E34: 45913 | F34: 2360 | G34: Tamil Nadu | H34: No | I34: 2000 | J34: 0 | K34: 180 | L34: 180 | M34: 0 | N34: Sep'25 | O34: 11/10/2025 | P34: Yes | R34: 100%
... A69: 33ACXPC1723B1Z3 | B69: VELS MEDIA | C69: 5221 | D69: Regular | E69: 45930 | F69: 35471.1 | G69: Tamil Nadu | H69: No | I69: 33782 | J69: 0 | K69: 844.55 | L69: 844.55 | M69: 0 | N69: Sep'25 | O69: 11/10/2025 | P69: Yes | R69: 100%
A70: 33AANFP0672L1ZY | B70: POLARIS LIGHTING & ENERGY MANAGEMENT | C70: FC/25-26/B0121 | D70: Regular | E70: 45918 | F70: 146648 | G70: Tamil Nadu | H70: No | I70: 124278 | J70: 0 | K70: 11185.02 | L70: 11185.02 | M70: 0 | N70: Sep'25 | O70: 10/10/2025 | P70: Yes | R70: 100% | S70: E-Invoice | T70: 31c35fe34f11538c83eab6c01f9a586dbe3310dd575accd19e46c94cb4f4b731 | U70: 18/09/2025
A71: 33EESPK2403H1ZL | B71: SWASTHIK TRADERS | C71: 546 | D71: Regular | E71: 45925 | F71: 16093 | G71: Tamil Nadu | H71: No | I71: 13638.14 | J71: 0 | K71: 1227.43 | L71: 1227.43 | M71: 0 | N71: Sep'25 | O71: 09/10/2025 | P71: Yes | R71: 100%
A72: 33ABPPD4344L1ZK | B72: INDIAN TRADING COMPANY | C72: ITC/25-26/2812 | D72: Regular | E72: 45910 | F72: 9230 | G72: Tamil Nadu | H72: No | I72: 7822.04 | J72: 0 | K72: 703.98 | L72: 703.98 | M72: 0 | N72: Sep'25 | O72: 09/10/2025 | P72: Yes | R72: 100%
A73: 33ABPPD4344L1ZK | B73: INDIAN TRADING COMPANY | C73: ITC/25-26/3127 | D73: Regular | E73: 45929 | F73: 7085 | G73: Tamil Nadu | H73: No | I73: 6004.24 | J73: 0 | K73: 540.38 | L73: 540.38 | M73: 0 | N73: Sep'25 | O73: 09/10/2025 | P73: Yes | R73: 100%
A74: 33ABPPD4344L1ZK | B74: INDIAN TRADING COMPANY | C74: ITC/25-26/3148 | D74: Regular | E74: 45930 | F74: 20670 | G74: Tamil Nadu | H74: No | I74: 17516.95 | J74: 0 | K74: 1576.53 | L74: 1576.53 | M74: 0 | N74: Sep'25 | O74: 09/10/2025 | P74: Yes | R74: 100%
...

Sheet B2BA
A1: Goods and Services Tax - GSTR-2B
A4: Amendments to previously filed invoices by supplier
A5: Original Details | C5: Revised Details
A6: Invoice number | B6: Invoice Date | C6: GSTIN of supplier | D6: Trade/Legal name | E6: Invoice Details | I6: Place of supply | J6: Supply Attract Reverse Charge | K6: Taxable Value (₹) | L6: Tax Amount | P6: Whether ITC to be reduced (Taxpayer's Input) | Q6: Amount declared by taxpayer for ITC reduction | U6: GSTR-1/IFF/GSTR-5 Period | V6: GSTR-1/IFF/GSTR-5 Filing Date | W6: ITC Availability | X6: Reason | Y6: Applicable % of Tax Rate
E7: Invoice number | F7: Invoice type | G7: Invoice Date | H7: Invoice Value(₹) | L7: Integrated Tax(₹) | M7: Central Tax(₹) | N7: State/UT Tax(₹) | O7: Cess(₹) | Q7: Integrated Tax(₹) | R7: Central Tax(₹) | S7: State/UT Tax(₹) | T7: Cess(₹)

Sheet B2B-CDNR
A1: Goods and Services Tax - GSTR-2B
A2: Debit/Credit notes (Original)
A3: GSTIN of supplier | B3: Trade/Legal name | C3: Note number | D3: Note type | E3: Note Supply type | F3: Note date | G3: Note Value (₹) | H3: Place of supply | I3: Supply Attract Reverse Charge | J3: Taxable Value (₹) | K3: Integrated Tax(₹) | L3: Central Tax(₹) | M3: State/UT Tax(₹) | N3: Cess(₹) | O3: Whether ITC to be reduced (Taxpayer's Input) | P3: Integrated Tax(₹) | Q3: Central Tax(₹) | R3: State/UT Tax(₹) | S3: Cess(₹) | T3: GSTR-1/IFF/GSTR-5 Period | U3: GSTR-1/IFF/GSTR-5 Filing Date | V3: ITC Availability | W3: Reason | X3: Applicable % of Tax Rate | Y3: Source | Z3: IRN | AA3: IRN Date
A4: 24AAACJ4897K1Z5 | B4: VICTORY CERATECH PVT.LTD. | C4: DHCN-GS/8 | D4: Credit Note | E4: Regular | F4: 45909 | G4: 10714 | H4: Tamil Nadu | I4: No | J4: 9080 | K4: 1634.4 | L4: 0 | M4: 0 | N4: 0 | O4: NA | P4: NA | Q4: NA | R4: NA | S4: NA | T4: Sep'25 | U4: 11/10/2025 | V4: Yes | X4: 100% | Y4: E-Invoice | Z4: 5b76f95016301fb1d4b67a934a223353578d19d1fe0525c564b78e7e4622faea | AA4: 09/09/2025
A5: 24AALCS1872N1ZU | B5: SIMPOLO VITRIFIED PRIVATE LIMITED | C5: 1110008051 | D5: Credit Note | E5: Regular | F5: 45909 | G5: 176 | H5: Tamil Nadu | I5: No | J5: 149.15 | K5: 26.85 | L5: 0 | M5: 0 | N5: 0 | O5: NA | P5: NA | Q5: NA | R5: NA | S5: NA | T5: Sep'25 | U5: 09/10/2025 | V5: Yes | X5: 100% | Y5: E-Invoice | Z5: eee06b7804986fd66d64e781b4c459f57e0fcb48b28f1a2c87a185a4fdf15817 | AA5: 10/09/2025
A6: 24AALCS1872N1ZU | B6: SIMPOLO VITRIFIED PRIVATE LIMITED | C6: 1110008052 | D6: Credit Note | E6: Regular | F6: 45909 | G6: 984 | H6: Tamil Nadu | I6: No | J6: 833.9 | K6: 150.1 | L6: 0 | M6: 0 | N6: 0 | O6: NA | P6: NA | Q6: NA | R6: NA | S6: NA | T6: Sep'25 | U6: 09/10/2025 | V6: Yes | X6: 100% | Y6: E-Invoice | Z6: 45fdcafe9f770a074bc743a1f88670131f38dfcf725372365467ab8aa8fa8f83 | AA6: 10/09/2025
A7: 24AALCS1872N1ZU | B7: SIMPOLO VITRIFIED PRIVATE LIMITED | C7: 1110009141 | D7: Credit Note | E7: Regular | F7: 45930 | G7: 1934 | H7: Tamil Nadu | I7: No | J7: 1638.98 | K7: 295.02 | L7: 0 | M7: 0 | N7: 0 | O7: NA | P7: NA | Q7: NA | R7: NA | S7: NA | T7: Sep'25 | U7: 09/10/2025 | V7: Yes | X7: 100% | Y7: E-Invoice | Z7: bf38326bb63a92244b4a0b6bf383bccb9a6a87d47cef036997e015f38ce2688b | AA7: 03/10/2025
A8: 24AALCS1872N1ZU | B8: SIMPOLO VITRIFIED PRIVATE LIMITED | C8: 1110009142 | D8: Credit Note | E8: Regular | F8: 45930 | G8: 5687 | H8: Tamil Nadu | I8: No | J8: 4819.49 | K8: 867.51 | L8: 0 | M8: 0 | N8: 0 | O8: NA | P8: NA | Q8: NA | R8: NA | S8: NA | T8: Sep'25 | U8: 09/10/2025 | V8: Yes | X8: 100% | Y8: E-Invoice | Z8: 9647236b3671c59fb559d78a52ad0269bccc0e835a8e25969df3e6dbfa53911d | AA8: 03/10/2025
A9: 24AALCS1872N1ZU | B9: SIMPOLO VITRIFIED PRIVATE LIMITED | C9: 1110009143 | D9: Credit Note | E9: Regular | F9: 45930 | G9: 474 | H9: Tamil Nadu | I9: No | J9: 401.7 | K9: 72.3 | L9: 0 | M9: 0 | N9: 0 | O9: NA | P9: NA | Q9: NA | R9: NA | S9: NA | T9: Sep'25 | U9: 09/10/2025 | V9: Yes | X9: 100% | Y9: E-Invoice | Z9: d42527264465def52dc10240d2f738a2b39fc6380c70fa111f11a94e1665d3cd | AA9: 03/10/2025
A10: 24AALCS1872N1ZU | B10: SIMPOLO VITRIFIED PRIVATE LIMITED | C10: 1110009144 | D10: Credit Note | E10: Regular | F10: 45930 | G10: 73 | H10: Tamil Nadu | I10: No | J10: 61.87 | K10: 11.13 | L10: 0 | M10: 0 | N10: 0 | O10: NA | P10: NA | Q10: NA | R10: NA | S10: NA | T10: Sep'25 | U10: 09/10/2025 | V10: Yes | X10: 100% | Y10: E-Invoice | Z10: 2aff0a538ec482c9703ec69114caa61c2f615863c34d2856841f63b661ef019f | AA10: 03/10/2025
A11: 24AALCS1872N1ZU | B11: SIMPOLO VITRIFIED PRIVATE LIMITED | C11: 1110009145 | D11: Credit Note | E11: Regular | F11: 45930 | G11: 749 | H11: Tamil Nadu | I11: No | J11: 634.74 | K11: 114.26 | L11: 0 | M11: 0 | N11: 0 | O11: NA | P11: NA | Q11: NA | R11: NA | S11: NA | T11: Sep'25 | U11: 09/10/2025 | V11: Yes | X11: 100% | Y11: E-Invoice | Z11: 28d656b765d75678d372d444d92b6c9f74d1fe318ae5b0516f4bfa32615b4bd5 | AA11: 03/10/2025
A12: 24AALCS1872N1ZU | B12: SIMPOLO VITRIFIED PRIVATE LIMITED | C12: 1110009146 | D12: Credit Note | E12: Regular | F12: 45930 | G12: 133 | H12: Tamil Nadu | I12: No | J12: 112.71 | K12: 20.29 | L12: 0 | M12: 0 | N12: 0 | O12: NA | P12: NA | Q12: NA | R12: NA | S12: NA | T12: Sep'25 | U12: 09/10/2025 | V12: Yes | X12: 100% | Y12: E-Invoice | Z12: 4350698c4101eac756b5de8428313ecf58734a44da4b2651fc3f158900d4b286 | AA12: 03/10/2025
A13: 24AALCS1872N1ZU | B13: SIMPOLO VITRIFIED PRIVATE LIMITED | C13: 1110009147 | D13: Credit Note | E13: Regular | F13: 45930 | G13: 813 | H13: Tamil Nadu | I13: No | J13: 688.98 | K13: 124.02 | L13: 0 | M13: 0 | N13: 0 | O13: NA | P13: NA | Q13: NA | R13: NA | S13: NA | T13: Sep'25 | U13: 09/10/2025 | V13: Yes | X13: 100% | Y13: E-Invoice | Z13: 2361150b7f9423e3f4df21d08e9416db3f85434084547e8cd13fd949a482ccca | AA13: 03/10/2025
A14: 24AALCS1872N1ZU | B14: SIMPOLO VITRIFIED PRIVATE LIMITED | C14: 1110009148 | D14: Credit Note | E14: Regular | F14: 45930 | G14: 5395 | H14: Tamil Nadu | I14: No | J14: 4572.03 | K14: 822.97 | L14: 0 | M14: 0 | N14: 0 | O14: NA | P14: NA | Q14: NA | R14: NA | S14: NA | T14: Sep'25 | U14: 09/10/2025 | V14: Yes | X14: 100% | Y14: E-Invoice | Z14: f3defc938e9551e34d8275eabf825aa4ca0a711cdb8e5ea205b037d6053f264c | AA14: 03/10/2025
A15: 24AALCS1872N1ZU | B15: SIMPOLO VITRIFIED PRIVATE LIMITED | C15: 1110009149 | D15: Credit Note | E15: Regular | F15: 45930 | G15: 9708 | H15: Tamil Nadu | I15: No | J15: 8227.12 | K15: 1480.88 | L15: 0 | M15: 0 | N15: 0 | O15: NA | P15: NA | Q15: NA | R15: NA | S15: NA | T15: Sep'25 | U15: 09/10/2025 | V15: Yes | X15: 100% | Y15: E-Invoice | Z15: 2bd203b6e05538f4b8813974fc2fc82fd36aaeb61aa2f3415f24f0e9ef723d10 | AA15: 03/10/2025
... A26: 24AALCS1872N1ZU | B26: SIMPOLO VITRIFIED PRIVATE LIMITED | C26: 1110009160 | D26: Credit Note | E26: Regular | F26: 45930 | G26: 3056 | H26: Tamil Nadu | I26: No | J26: 2589.83 | K26: 466.17 | L26: 0 | M26: 0 | N26: 0 | O26: NA | P26: NA | Q26: NA | R26: NA | S26: NA | T26: Sep'25 | U26: 09/10/2025 | V26: Yes | X26: 100% | Y26: E-Invoice | Z26: 4352b14400fcf9f8df6de7c25b9b09c7ca38972e304cd2cf2550ee5f4a561a08 | AA26: 03/10/2025
A27: 37AAACP6224A1ZW | B27: PRISM JOHNSON LIMITED | C27: 1003044848 | D27: Debit Note | E27: Regular | F27: 45915 | G27: 4865 | H27: Tamil Nadu | I27: No | J27: 4122.88 | K27: 742.12 | L27: 0 | M27: 0 | N27: 0 | T27: Sep'25 | U27: 09/10/2025 | V27: Yes | X27: 100% | Y27: E-Invoice | Z27: 3769892b0c708b89549dc99ec0707618f2a050b82aa24c7a78dd5283a7a16b6a | AA27: 30/09/2025
A28: 33ACJFS0911K1Z7 | B28: SRI MURUGAN BATH | C28: 4 | D28: Credit Note | E28: Regular | F28: 45901 | G28: 17421 | H28: Tamil Nadu | I28: No | J28: 14763.44 | K28: 0 | L28: 1328.71 | M28: 1328.71 | N28: 0 | O28: NA | P28: NA | Q28: NA | R28: NA | S28: NA | T28: Sep'25 | U28: 11/10/2025 | V28: Yes | X28: 100%
A29: 33ABMPU9655L1ZQ | B29: AYYAN ELECTRICALS | C29: SRTN-25/26-105 | D29: Credit Note | E29: Regular | F29: 45926 | G29: 4310 | H29: Tamil Nadu | I29: No | J29: 3652.54 | K29: 0 | L29: 328.73 | M29: 328.73 | N29: 0 | O29: NA | P29: NA | Q29: NA | R29: NA | S29: NA | T29: Sep'25 | U29: 11/10/2025 | V29: Yes | X29: 100%
A30: 24AAECS0763K1ZB | B30: SOMANY CERAMICS LIMITED | C30: 7225012050 | D30: Credit Note | E30: Regular | F30: 45904 | G30: 6188.59 | H30: Tamil Nadu | I30: No | J30: 5244.56 | K30: 944.03 | L30: 0 | M30: 0 | N30: 0 | O30: NA | P30: NA | Q30: NA | R30: NA | S30: NA | T30: Sep'25 | U30: 10/10/2025 | V30: Yes | X30: 100%
A31: 24AAECS0763K1ZB | B31: SOMANY CERAMICS LIMITED | C31: 7225012051 | D31: Credit Note | E31: Regular | F31: 45904 | G31: 4843.27 | H31: Tamil Nadu | I31: No | J31: 4104.47 | K31: 738.8 | L31: 0 | M31: 0 | N31: 0 | O31: NA | P31: NA | Q31: NA | R31: NA | S31: NA | T31: Sep'25 | U31: 10/10/2025 | V31: Yes | X31: 100%
A32: 24AAECS0763K1ZB | B32: SOMANY CERAMICS LIMITED | C32: 7225012052 | D32: Credit Note | E32: Regular | F32: 45904 | G32: 3899.94 | H32: Tamil Nadu | I32: No | J32: 3305.03 | K32: 594.91 | L32: 0 | M32: 0 | N32: 0 | O32: NA | P32: NA | Q32: NA | R32: NA | S32: NA | T32: Sep'25 | U32: 10/10/2025 | V32: Yes | X32: 100%
A33: 24AAECS0763K1ZB | B33: SOMANY CERAMICS LIMITED | C33: 7225012073 | D33: Credit Note | E33: Regular | F33: 45904 | G33: 3430.16 | H33: Tamil Nadu | I33: No | J33: 2906.91 | K33: 523.25 | L33: 0 | M33: 0 | N33: 0 | O33: NA | P33: NA | Q33: NA | R33: NA | S33: NA | T33: Sep'25 | U33: 10/10/2025 | V33: Yes | X33: 100%
A34: 24AAECS0763K1ZB | B34: SOMANY CERAMICS LIMITED | C34: 9025001940 | D34: Credit Note | E34: Regular | F34: 45905 | G34: 3050.3 | H34: Tamil Nadu | I34: No | J34: 2585 | K34: 465.3 | L34: 0 | M34: 0 | N34: 0 | O34: NA | P34: NA | Q34: NA | R34: NA | S34: NA | T34: Sep'25 | U34: 10/10/2025 | V34: Yes | X34: 100%
J36: =SUM(J4:J35) -> 108996.19 | K36: =SUM(K4:K35) -> 16304.45 | L36: =SUM(L4:L35) -> 1657.44 | M36: =SUM(M4:M35) -> 1657.44

Sheet B2B-CDNRA
A1: Goods and Services Tax - GSTR-2B
A4: Amendments to previously filed Credit/Debit notes by supplier
A5: Original Details | D5: Revised Details
A6: Note type | B6: Note number | C6: Note date | D6: GSTIN of supplier | E6: Trade/Legal name | F6: Credit note/Debit note details | K6: Place of supply | L6: Supply Attract Reverse Charge | M6: Taxable Value (₹) | N6: Tax Amount | R6: Whether ITC to be reduced (Taxpayer's Input) | S6: Amount declared by taxpayer for ITC reduction | W6: GSTR-1/IFF/GSTR-5 Period | X6: GSTR-1/IFF/GSTR-5 Filing Date | Y6: ITC Availability | Z6: Reason | AA6: Applicable % of Tax Rate
F7: Note number | G7: Note type | H7: Note Supply type | I7: Note date | J7: Note Value (₹) | N7: Integrated Tax(₹) | O7: Central Tax(₹) | P7: State/UT Tax(₹) | Q7: Cess(₹) | S7: Integrated Tax(₹) | T7: Central Tax(₹) | U7: State/UT Tax(₹) | V7: Cess(₹)

Sheet ECO
A1: Goods and Services Tax - GSTR-2B
A4: Documents reported by ECO on which ECO is liable to pay tax u/s 9(5)
A5: GSTIN of ECO | B5: Trade/Legal name | C5: Document details | G5: Place of supply | H5: Taxable value (₹) | I5: Tax amount | M5: GSTR-1/1A/IFF period | N5: GSTR-1/1A/IFF filing date | O5: ITC availability | P5: Reason | Q5: Source | R5: IRN | S5: IRN Date
C6: Document number | D6: Document type | E6: Document date | F6: Document value(₹) | I6: Integrated Tax(₹) | J6: Central Tax(₹) | K6: State/UT Tax(₹) | L6: Cess(₹)

Sheet ECOA
A1: Goods and Services Tax - GSTR-2B
A4: Amendments to documents reported by ECO on which ECO is liable to pay tax u/s 9(5)
A5: Original Details | C5: Revised Details
A6: Document number | B6: Document date | C6: GSTIN of ECO | D6: Trade/Legal name | E6: Document details | I6: Place of supply | J6: Taxable value (₹) | K6: Tax amount | O6: Whether ITC to be reduced (Taxpayer's Input) | P6: Amount declared by taxpayer for ITC reduction | T6: GSTR-1/1A/IFF period | U6: GSTR-1/1A/IFF filing date | V6: ITC availability | W6: Reason
E7: Document number | F7: Document type | G7: Document date | H7: Document value(₹) | K7: Integrated Tax(₹) | L7: Central Tax(₹) | M7: State/UT Tax(₹) | N7: Cess(₹) | P7: Integrated Tax(₹) | Q7: Central Tax(₹) | R7: State/UT Tax(₹) | S7: Cess(₹)

Sheet ISD
A1: Goods and Services Tax - GSTR-2B
A4: ISD Credits
A5: GSTIN of ISD | B5: Trade/Legal name | C5: ISD Document type | D5: ISD Document number | E5: ISD Document date | F5: Original Invoice Number | G5: Original invoice date | H5: Input tax distribution by ISD | L5: ISD GSTR-6 Period | M5: ISD GSTR-6 Filing Date | N5: Eligibility of ITC
H6: Integrated Tax(₹) | I6: Central Tax(₹) | J6: State/UT Tax(₹) | K6: Cess(₹)

Sheet ISDA
A1: Goods and Services Tax - GSTR-2B
A4: Amendments ISD Credits received
A5: Original Details | D5: Revised Details
A6: ISD Document type | B6: Document Number | C6: Document date | D6: GSTIN of ISD | E6: Trade/Legal name | F6: ISD Document type | G6: ISD Document number | H6: ISD Document date | I6: Original Invoice Number | J6: Original invoice date | K6: Input tax distribution by ISD | O6: ISD GSTR-6 Period | P6: ISD GSTR-6 Filing Date | Q6: Eligibility of ITC
K7: Integrated Tax(₹) | L7: Central Tax(₹) | M7: State/UT Tax(₹) | N7: Cess(₹)

Sheet IMPG
A1: Goods and Services Tax - GSTR-2B
A4: Import of goods from overseas on bill of entry
A5: Icegate Reference Date | B5: Port Code | C5: Bill of Entry Details | F5: Amount of tax (₹) | H5: Amended (Yes)
C6: Number | D6: Date | E6: Taxable Value | F6: Integrated Tax(₹) | G6: Cess(₹)

Sheet IMPGSEZ
A1: Goods and Services Tax - GSTR-2B
A4: Import of goods from SEZ units/developers on bill of entry
A5: GSTIN of supplier | B5: Trade/Legal name | C5: Icegate Reference Date | D5: Port Code | E5: Bill of Entry Details | H5: Amount of tax (₹) | J5: Amended (Yes)
E6: Number | F6: Date | G6: Taxable Value | H6: Integrated Tax(₹) | I6: Cess(₹)

Sheet B2B (ITC Reversal)
A1: Goods and Services Tax - GSTR-2B
A4: ITC Reversed - Others
A5: GSTIN of supplier | B5: Trade/Legal name | C5: Invoice Details | G5: Place of supply | H5: Supply Attract Reverse Charge | I5: Taxable Value (₹) | J5: Tax Amount | N5: GSTR-1/IFF Period | O5: GSTR-1/IFF Filing Date | P5: ITC Availability | Q5: Reason | R5: Applicable % of Tax Rate | S5: Source | T5: IRN | U5: IRN Date
C6: Invoice number | D6: Invoice type | E6: Invoice Date | F6: Invoice Value(₹) | J6: Integrated Tax(₹) | K6: Central Tax(₹) | L6: State/UT Tax(₹) | M6: Cess(₹)

Sheet B2BA (ITC Reversal)
A1: Goods and Services Tax - GSTR-2B
A4: Amendments to previously filed invoices by supplier (ITC reversal)
A5: Original Details | C5: Revised Details
A6: Invoice number | B6: Invoice Date | C6: GSTIN of supplier | D6: Trade/Legal name | E6: Invoice Details | I6: Place of supply | J6: Supply Attract Reverse Charge | K6: Taxable Value (₹) | L6: Tax Amount | P6: GSTR-1/IFF Period | Q6: GSTR-1/IFF Filing Date | R6: ITC Availability | S6: Reason | T6: Applicable % of Tax Rate
E7: Invoice number | F7: Invoice type | G7: Invoice Date | H7: Invoice Value(₹) | L7: Integrated Tax(₹) | M7: Central Tax(₹) | N7: State/UT Tax(₹) | O7: Cess(₹)

Sheet B2B-DNR
A1: Goods and Services Tax - GSTR-2B
A4: Debit notes (Original)
A5: GSTIN of supplier | B5: Trade/Legal name | C5: Debit note details | H5: Place of supply | I5: Supply Attract Reverse Charge | J5: Taxable Value (₹) | K5: Tax Amount | O5: GSTR-1/IFF Period | P5: GSTR-1/IFF Filing Date | Q5: ITC Availability | R5: Reason | S5: Applicable % of Tax Rate | T5: Source | U5: IRN | V5: IRN Date
C6: Note number | D6: Note type | E6: Note Supply type | F6: Note date | G6: Note Value (₹) | K6: Integrated Tax(₹) | L6: Central Tax(₹) | M6: State/UT Tax(₹) | N6: Cess(₹)

Sheet B2B-DNRA
A1: Goods and Services Tax - GSTR-2B
A4: Amendments to previously filed Debit notes by supplier
A5: Original Details | D5: Revised Details
A6: Note type | B6: Note number | C6: Note date | D6: GSTIN of supplier | E6: Trade/Legal name | F6: Debit note details | K6: Place of supply | L6: Supply Attract Reverse Charge | M6: Rate(%) | N6: Taxable Value (₹) | R6: Tax Amount | S6: GSTR-1/IFF Period | T6: GSTR-1/IFF Filing Date | U6: ITC Availability | V6: Reason | W6: Applicable % of Tax Rate
F7: Note number | G7: Note type | H7: Note Supply type | I7: Note date | J7: Note Value (₹) | N7: Integrated Tax(₹) | O7: Central Tax(₹) | P7: State/UT Tax(₹) | Q7: Cess(₹)

Sheet B2B(Rejected)
A1: Goods and Services Tax - GSTR-2B
A4: ITC Rejected for taxable inward supplies received from registered persons
A5: GSTIN of supplier | B5: Trade/Legal name | C5: Invoice Details | G5: Place of supply | H5: Taxable Value (₹) | I5: Tax Amount | M5: Remarks | N5: GSTR-1/IFF/GSTR-5 Period | O5: GSTR-1/IFF/GSTR-5 Filing Date | P5: Applicable % of Tax Rate | Q5: Source | R5: IRN | S5: IRN Date
C6: Invoice number | D6: Invoice type | E6: Invoice Date | F6: Invoice Value(₹) | I6: Integrated Tax(₹) | J6: Central Tax(₹) | K6: State/UT Tax(₹) | L6: Cess(₹)

Sheet B2BA(Rejected)
A1: Goods and Services Tax - GSTR-2B
A4: ITC Rejected for amendments to previously filed invoices by supplier
A5: Original Details | C5: Revised Details
A6: Invoice number | B6: Invoice Date | C6: GSTIN of supplier | D6: Trade/Legal name | E6: Invoice Details | I6: Place of supply | J6: Taxable Value (₹) | K6: Tax Amount | O6: Remarks | P6: GSTR-1/IFF/GSTR-5 Period | Q6: GSTR-1/IFF/GSTR-5 Filing Date | R6: Applicable % of Tax Rate
E7: Invoice number | F7: Invoice type | G7: Invoice Date | H7: Invoice Value(₹) | K7: Integrated Tax(₹) | L7: Central Tax(₹) | M7: State/UT Tax(₹) | N7: Cess(₹)

Sheet B2B-CDNR(Rejected)
A1: Goods and Services Tax - GSTR-2B
A4: ITC Rejected for Debit/Credit notes (Original)
A5: GSTIN of supplier | B5: Trade/Legal name | C5: Credit note/Debit note details | H5: Place of supply | I5: Taxable Value (₹) | J5: Tax Amount | N5: Remarks | O5: GSTR-1/IFF/GSTR-5 Period | P5: GSTR-1/IFF/GSTR-5 Filing Date | Q5: Applicable % of Tax Rate | R5: Source | S5: IRN | T5: IRN Date
C6: Note number | D6: Note type | E6: Note Supply type | F6: Note date | G6: Note Value (₹) | J6: Integrated Tax(₹) | K6: Central Tax(₹) | L6: State/UT Tax(₹) | M6: Cess(₹)

Sheet B2B-CDNRA(Rejected)
A1: Goods and Services Tax - GSTR-2B
A4: ITC Rejected for amendments to previously filed Credit/Debit notes by supplier
A5: Original Details | D5: Revised Details
A6: Note type | B6: Note number | C6: Note date | D6: GSTIN of supplier | E6: Trade/Legal name | F6: Credit note/Debit note details | K6: Place of supply | L6: Taxable Value (₹) | M6: Tax Amount | Q6: Remarks | R6: GSTR-1/IFF/GSTR-5 Period | S6: GSTR-1/IFF/GSTR-5 Filing Date | T6: Applicable % of Tax Rate
F7: Note number | G7: Note type | H7: Note Supply type | I7: Note date | J7: Note Value (₹) | M7: Integrated Tax(₹) | N7: Central Tax(₹) | O7: State/UT Tax(₹) | P7: Cess(₹)

Sheet ECO(Rejected)
A1: Goods and Services Tax - GSTR-2B
A4: ITC Rejected for documents reported by ECO on which ECO is liable to pay tax us 9(5)
A5: GSTIN of ECO | B5: Trade/Legal name | C5: Document details | G5: Place of supply | H5: Taxable value (₹) | I5: Tax amount | M5: Remarks | N5: GSTR-1/1A/IFF period | O5: GSTR-1/1A/IFF filing date | P5: Source | Q5: IRN | R5: IRN Date
C6: Document number | D6: Document type | E6: Document date | F6: Document value(₹) | I6: Integrated Tax(₹) | J6: Central Tax(₹) | K6: State/UT Tax(₹) | L6: Cess(₹)

Sheet ECOA(Rejected)
A1: Goods and Services Tax - GSTR-2B
A4: ITC Rejected for amendments to documents reported by ECO on which ECO is liable to pay tax u/s 9(5)
A5: Original Details | C5: Revised Details
A6: Document number | B6: Document date | C6: GSTIN of ECO | D6: Trade/Legal name | E6: Document details | I6: Place of supply | J6: Taxable value (₹) | K6: Tax amount | O6: Remarks | P6: GSTR-1/1A/IFF period | Q6: GSTR-1/1A/IFF filing date
E7: Document number | F7: Document type | G7: Document date | H7: Document value(₹) | K7: Integrated Tax(₹) | L7: Central Tax(₹) | M7: State/UT Tax(₹) | N7: Cess(₹)

Sheet ISD(Rejected)
A1: Goods and Services Tax - GSTR-2B
A4: ITC Rejected for ISD Credits
A5: GSTIN of ISD | B5: Trade/Legal name | C5: ISD Document type | D5: ISD Document number | E5: ISD Document date | F5: Original Invoice Number | G5: Original invoice date | H5: Input tax distribution by ISD | L5: ISD GSTR-6 Period | M5: ISD GSTR-6 Filing Date
H6: Integrated Tax(₹) | I6: Central Tax(₹) | J6: State/UT Tax(₹) | K6: Cess(₹)

Sheet ISDA(Rejected)
A1: Goods and Services Tax - GSTR-2B
A4: ITC Rejected for amendments of ISD Credits received
A5: Original Details | D5: Revised Details
A6: ISD Document type | B6: Document Number | C6: Document date | D6: GSTIN of ISD | E6: Trade/Legal name | F6: ISD Document type | G6: ISD Document number | H6: ISD Document date | I6: Original Invoice Number | J6: Original invoice date | K6: Input tax distribution by ISD | O6: ISD GSTR-6 Period | P6: ISD GSTR-6 Filing Date
K7: Integrated Tax(₹) | L7: Central Tax(₹) | M7: State/UT Tax(₹) | N7: Cess(₹)
